<!--URDF generated by ONSHAPE BY PTC INC, 1.215-->
<robot name="torso_assembly">
    <link name="part_2">
        <inertial>
            <mass value="2.996" />
            <origin xyz="0.0589806 0.0116765 0.108266" rpy="0 -0 0" />
            <inertia ixx="0.0270255" ixy="0" ixz="0" iyy="0.0334115" iyz="-0.00118593" izz="0.0242411" />
        </inertial>
        <visual>
            <origin xyz="0.0589806 1.38778e-17 -0.0699562" rpy="0 -0 0" />
            <geometry>
                <mesh filename="package://torso_assembly/meshes/Part_2.stl" scale="1 1 1" />
            </geometry>
            <material name="0.917647_0.917647_0.917647_0.000000_0.000000">
                <color rgba="0.917647 0.917647 0.917647 1" />
            </material>
        </visual>
    </link>
    <link name="pelvis">
        <inertial>
            <mass value="4.24496" />
            <origin xyz="3.25647e-18 0.00247762 -0.00036569" rpy="0 -0 0" />
            <inertia ixx="0.0142013" ixy="0" ixz="0" iyy="0.0134283" iyz="-0.000383277" izz="0.0100864" />
        </inertial>
        <visual>
            <origin xyz="0 0 0" rpy="0 -0 0" />
            <geometry>
                <mesh filename="package://torso_assembly/meshes/Pelvis.stl" scale="1 1 1" />
            </geometry>
            <material name="0.647059_0.647059_0.647059_0.000000_0.000000">
                <color rgba="0.647059 0.647059 0.647059 1" />
            </material>
        </visual>
    </link>
    <link name="root" />
    <joint name="hanging_node_to_root_joint" type="fixed">
        <origin xyz="-0.0414369 0.013591 -0.00683823" rpy="0 -0 0" />
        <axis xyz="0 0 1" />
        <parent link="root" />
        <child link="pelvis" />
    </joint>
    <joint name="revolute_1" type="continuous">
        <origin xyz="-0.0589806 -1.38778e-17 0.0699562" rpy="0 -0 0" />
        <axis xyz="1 0 0" />
        <parent link="pelvis" />
        <child link="part_2" />
    </joint>
</robot>
