<!--URDF generated by ONSHAPE BY PTC INC, 1.215-->
<robot name="assembly_1">
    <link name="part_1">
        <inertial>
            <mass value="0.000142254" />
            <origin xyz="0 -3.04468e-05 -0.0288044" rpy="0 -0 0" />
            <inertia ixx="1.04553e-07" ixy="0" ixz="0" iyy="1.05192e-07" iyz="-6.06176e-09" izz="1.72955e-07" />
        </inertial>
        <visual>
            <origin xyz="0 -0.002 0.169" rpy="0 -0 0" />
            <geometry>
                <mesh filename="package://assembly_1/meshes/Part_1.stl" scale="1 1 1" />
            </geometry>
            <material name="0.615686_0.811765_0.929412_0.000000_0.000000">
                <color rgba="0.615686 0.811765 0.929412 1" />
            </material>
        </visual>
    </link>
    <link name="part_2">
        <inertial>
            <mass value="0.000120635" />
            <origin xyz="0.0130536 -0.00173308 -0.0126928" rpy="0 -0 0" />
            <inertia ixx="1.99621e-07" ixy="-1.79628e-09" ixz="-8.41712e-09" iyy="1.35135e-07" iyz="-1.12319e-08" izz="8.11219e-08" />
        </inertial>
        <visual>
            <origin xyz="0.002 -6.93889e-18 0.1" rpy="0 -0 0" />
            <geometry>
                <mesh filename="package://assembly_1/meshes/Part_2.stl" scale="1 1 1" />
            </geometry>
            <material name="0.647059_0.647059_0.647059_0.000000_0.000000">
                <color rgba="0.647059 0.647059 0.647059 1" />
            </material>
        </visual>
    </link>
    <link name="part_3">
        <inertial>
            <mass value="0.000256227" />
            <origin xyz="-0.0164976 -3.16059e-17 -0.12692" rpy="0 -0 0" />
            <inertia ixx="1.41219e-06" ixy="0" ixz="1.55028e-08" iyy="1.23886e-06" iyz="0" izz="1.86962e-07" />
        </inertial>
        <visual>
            <origin xyz="-0.002 -1.38778e-17 -0.1" rpy="0 -0 0" />
            <geometry>
                <mesh filename="package://assembly_1/meshes/Part_3.stl" scale="1 1 1" />
            </geometry>
            <material name="0.231373_0.380392_0.705882_0.000000_0.000000">
                <color rgba="0.231373 0.380392 0.705882 1" />
            </material>
        </visual>
    </link>
    <link name="part_4">
        <inertial>
            <mass value="0.0001934" />
            <origin xyz="0.00786672 1.06677e-16 -0.0716487" rpy="0 -0 0" />
            <inertia ixx="5.76997e-07" ixy="0" ixz="2.47087e-08" iyy="4.69141e-07" iyz="0" izz="1.64009e-07" />
        </inertial>
        <visual>
            <origin xyz="0 1.66956e-17 -0.26" rpy="0 -0 0" />
            <geometry>
                <mesh filename="package://assembly_1/meshes/Part_4.stl" scale="1 1 1" />
            </geometry>
            <material name="0.768627_0.886275_0.952941_0.000000_0.000000">
                <color rgba="0.768627 0.886275 0.952941 1" />
            </material>
        </visual>
    </link>
    <link name="part_5">
        <inertial>
            <mass value="0.000126008" />
            <origin xyz="4.91788e-12 -0.0124546 -0.0250019" rpy="0 -0 0" />
            <inertia ixx="1.66264e-07" ixy="0" ixz="0" iyy="2.10166e-07" iyz="3.29365e-08" izz="1.71031e-07" />
        </inertial>
        <visual>
            <origin xyz="7.51078e-18 -0.002 -0.318" rpy="0 -0 0" />
            <geometry>
                <mesh filename="package://assembly_1/meshes/Part_5.stl" scale="1 1 1" />
            </geometry>
            <material name="0.972549_0.529412_0.003922_0.000000_0.000000">
                <color rgba="0.972549 0.529412 0.00392157 1" />
            </material>
        </visual>
    </link>
    <link name="part_6">
        <inertial>
            <mass value="7.54387e-05" />
            <origin xyz="0.044959 0.0174626 -3.01059e-12" rpy="0 -0 0" />
            <inertia ixx="1.09687e-07" ixy="-1.71797e-08" ixz="0" iyy="1.47521e-07" iyz="0" izz="1.09524e-07" />
        </inertial>
        <visual>
            <origin xyz="0.058 2.0383e-17 -0.318" rpy="0 -0 0" />
            <geometry>
                <mesh filename="package://assembly_1/meshes/Part_6.stl" scale="1 1 1" />
            </geometry>
            <material name="0.498039_0.498039_0.498039_0.000000_0.000000">
                <color rgba="0.498039 0.498039 0.498039 1" />
            </material>
        </visual>
    </link>
    <link name="part_7">
        <inertial>
            <mass value="4.2223e-05" />
            <origin xyz="-0.078 -1.9929e-16 0.318" rpy="0 -0 0" />
            <inertia ixx="7.46503e-08" ixy="0" ixz="0" iyy="4.29549e-08" iyz="0" izz="4.29549e-08" />
        </inertial>
        <visual>
            <origin xyz="0 0 0" rpy="0 -0 0" />
            <geometry>
                <mesh filename="package://assembly_1/meshes/Part_7.stl" scale="1 1 1" />
            </geometry>
            <material name="0.980392_0.713725_0.003922_0.000000_0.000000">
                <color rgba="0.980392 0.713726 0.00392157 1" />
            </material>
        </visual>
    </link>
    <link name="root" />
    <joint name="ankle_pitch" type="continuous">
        <origin xyz="-0.004 -1.07553e-16 -0.2" rpy="2.81893e-17 1.43967e-29 3.46945e-18" />
        <axis xyz="1 0 0" />
        <parent link="part_3" />
        <child link="part_2" />
    </joint>
    <joint name="ankle_roll" type="continuous">
        <origin xyz="0.002 0.002 -0.069" rpy="1.31993e-15 -0.0163287 5.43677e-15" />
        <axis xyz="0 -1 0" />
        <parent link="part_2" />
        <child link="part_1" />
    </joint>
    <joint name="fixed_node_to_root_joint" type="fixed">
        <origin xyz="-0.076637 -0.0162221 -0.0319212" rpy="0 -0 0" />
        <axis xyz="0 0 1" />
        <parent link="root" />
        <child link="part_7" />
    </joint>
    <joint name="hip_pitch" type="continuous">
        <origin xyz="-0.058 -6.93889e-18 0.318" rpy="0 -0 0" />
        <axis xyz="-1 0 0" />
        <parent link="part_7" />
        <child link="part_6" />
    </joint>
    <joint name="hip_roll" type="continuous">
        <origin xyz="0.058 0.002 2.22045e-16" rpy="1.01424e-69 4.21297e-35 4.81482e-35" />
        <axis xyz="0 -1 0" />
        <parent link="part_6" />
        <child link="part_5" />
    </joint>
    <joint name="knee" type="continuous">
        <origin xyz="0.002 4.51028e-17 -0.16" rpy="-4.20871e-17 -1.63934e-18 -6.93889e-18" />
        <axis xyz="-1 0 0" />
        <parent link="part_4" />
        <child link="part_3" />
    </joint>
    <joint name="yaw" type="continuous">
        <origin xyz="6.93889e-17 -0.002 -0.058" rpy="3.65211e-18 -1.83011e-18 3.46945e-18" />
        <axis xyz="0 6.12323e-17 -1" />
        <parent link="part_5" />
        <child link="part_4" />
    </joint>
</robot>
