<!--URDF generated by ONSHAPE BY PTC INC, 1.215-->
<robot name="arm_assembly">
    <link name="part_1">
        <inertial>
            <mass value="0.17227" />
            <origin xyz="-0.0781099 -6.37854e-17 1.82677e-16" rpy="0 -0 0" />
            <inertia ixx="0.000304573" ixy="0" ixz="0" iyy="0.000203968" iyz="0" izz="0.000203968" />
        </inertial>
        <visual>
            <origin xyz="0 0 0" rpy="0 -0 0" />
            <geometry>
                <mesh filename="package://arm_assembly/meshes/Part_1.stl" scale="1 1 1" />
            </geometry>
            <material name="0.615686_0.811765_0.929412_0.000000_0.000000">
                <color rgba="0.615686 0.811765 0.929412 1" />
            </material>
        </visual>
    </link>
    <link name="part_2">
        <inertial>
            <mass value="0.179724" />
            <origin xyz="0.0329553 -0.00486958 -0.0195905" rpy="0 -0 0" />
            <inertia ixx="0.000393652" ixy="1.3893e-05" ixz="5.51231e-05" iyy="0.000379124" iyz="-3.03795e-05" izz="0.000209327" />
        </inertial>
        <visual>
            <origin xyz="0.0481099 -1.22465e-18 0" rpy="0 -0 0" />
            <geometry>
                <mesh filename="package://arm_assembly/meshes/Part_2.stl" scale="1 1 1" />
            </geometry>
            <material name="0.647059_0.647059_0.647059_0.000000_0.000000">
                <color rgba="0.647059 0.647059 0.647059 1" />
            </material>
        </visual>
    </link>
    <link name="part_3">
        <inertial>
            <mass value="0.236776" />
            <origin xyz="-2.07904e-11 0.00576515 -0.0427323" rpy="0 -0 0" />
            <inertia ixx="0.000429886" ixy="-6.71931e-13" ixz="-8.84514e-14" iyy="0.000515247" iyz="-3.80957e-05" izz="0.000372178" />
        </inertial>
        <visual>
            <origin xyz="1.73472e-18 0.002 0.054" rpy="0 -0 0" />
            <geometry>
                <mesh filename="package://arm_assembly/meshes/Part_3.stl" scale="1 1 1" />
            </geometry>
            <material name="0.917647_0.917647_0.917647_0.000000_0.000000">
                <color rgba="0.917647 0.917647 0.917647 1" />
            </material>
        </visual>
    </link>
    <link name="part_4">
        <inertial>
            <mass value="0.763075" />
            <origin xyz="-0.0227382 -4.06552e-12 -0.0592339" rpy="0 -0 0" />
            <inertia ixx="0.00122257" ixy="-3.25123e-13" ixz="-9.06597e-05" iyy="0.000926563" iyz="-4.80575e-13" izz="0.00067842" />
        </inertial>
        <visual>
            <origin xyz="0 -2.44929e-18 0.148" rpy="0 -0 0" />
            <geometry>
                <mesh filename="package://arm_assembly/meshes/Part_4.stl" scale="1 1 1" />
            </geometry>
            <material name="0.768627_0.886275_0.952941_0.000000_0.000000">
                <color rgba="0.768627 0.886275 0.952941 1" />
            </material>
        </visual>
    </link>
    <link name="part_5">
        <inertial>
            <mass value="2.51045" />
            <origin xyz="0.000114307 1.48718e-18 -0.0911714" rpy="0 -0 0" />
            <inertia ixx="0.00980286" ixy="0" ixz="-0.000852308" iyy="0.00900951" iyz="0" izz="0.00253607" />
        </inertial>
        <visual>
            <origin xyz="0.002 0 0.22" rpy="0 -0 0" />
            <geometry>
                <mesh filename="package://arm_assembly/meshes/Part_5.stl" scale="1 1 1" />
            </geometry>
            <material name="0.972549_0.529412_0.003922_0.000000_0.000000">
                <color rgba="0.972549 0.529412 0.00392157 1" />
            </material>
        </visual>
    </link>
    <link name="root" />
    <joint name="fixed_node_to_root_joint" type="fixed">
        <origin xyz="0.00801965 -0.0943723 0.0672566" rpy="0 -0 0" />
        <axis xyz="0 0 1" />
        <parent link="root" />
        <child link="part_1" />
    </joint>
    <joint name="revolute_1" type="continuous">
        <origin xyz="-0.0481099 0 0" rpy="0 -0 0" />
        <axis xyz="1 0 0" />
        <parent link="part_1" />
        <child link="part_2" />
    </joint>
    <joint name="revolute_2" type="continuous">
        <origin xyz="0.0481099 -0.002 -0.054" rpy="0 -0 0" />
        <axis xyz="0 1 0" />
        <parent link="part_2" />
        <child link="part_3" />
    </joint>
    <joint name="revolute_3" type="continuous">
        <origin xyz="1.73472e-18 0.002 -0.094" rpy="0 -0 0" />
        <axis xyz="0 0 1" />
        <parent link="part_3" />
        <child link="part_4" />
    </joint>
    <joint name="revolute_4" type="continuous">
        <origin xyz="-0.002 0 -0.072" rpy="-0.0160109 0 0" />
        <axis xyz="1 0 0" />
        <parent link="part_4" />
        <child link="part_5" />
    </joint>
</robot>
