<mujoco model="MuJoCo Model">
  <compiler angle="radian" meshdir="assets/"/>

  <asset>
    <mesh name="Ankle" file="Ankle.stl"/>
    <mesh name="Foot" file="Foot.stl"/>
    <mesh name="Hip" file="Hip.stl"/>
    <mesh name="Hip_Pitch" file="Hip_Pitch.stl"/>
    <mesh name="Hip_Roll" file="Hip_Roll.stl"/>
    <mesh name="Part_1" file="Part_1.stl"/>
    <mesh name="Part_2" file="Part_2.stl"/>
    <mesh name="Part_2_1" file="Part_2_1.stl"/>
    <mesh name="Part_3" file="Part_3.stl"/>
    <mesh name="Part_4" file="Part_4.stl"/>
    <mesh name="Part_5" file="Part_5.stl"/>
    <mesh name="Pelvis" file="Pelvis.stl"/>
    <mesh name="Shin" file="Shin.stl"/>
    <mesh name="Thigh" file="Thigh.stl"/>
  </asset>

  <worldbody>
    <body name="base" pos="0 0 1">
      <joint name="base_free" type="free"/>
      <frame name="_mount">
        <body name="root">
          <body name="pelvis">
            <inertial pos="0 -0.0675224 -0.0165033" quat="0.998412 -0.0563392 0 0" mass="4.24496" diaginertia="0.0142013 0.0134717 0.010043"/>
            <geom pos="0 -0.07 -0.0161376" type="mesh" rgba="0.647059 0.647059 0.647059 1" mesh="Pelvis"/>
            <body name="hip_1" pos="0.03 -0.07 -0.0791376">
              <inertial pos="0.02 0 0" mass="0.114847" diaginertia="0.000203049 0.000116837 0.000116837"/>
              <geom pos="0.098 0 -0.318" type="mesh" rgba="0.980392 0.713726 0.00392157 1" mesh="Hip"/>
              <body name="hip_pitch_1" pos="0.04 0 0">
                <inertial pos="0.044959 0.0174626 -3.01048e-12" quat="0.399887 0.399887 0.583173 0.583173" mass="0.205193" diaginertia="0.000419309 0.000297906 0.000280298"/>
                <joint name="hip_pitch_1" pos="0 0 0" axis="1 0 0"/>
                <geom pos="0.058 0 -0.318" quat="1 0 0 0" type="mesh" rgba="0.498039 0.498039 0.498039 1" mesh="Hip_Pitch"/>
                <body name="hip_roll_1" pos="0.058 0.002 0">
                  <inertial pos="4.91788e-12 -0.0124546 -0.0250019" quat="0.68358 0.180882 -0.180882 0.68358" mass="0.342742" diaginertia="0.000622632 0.000452239 0.000414222"/>
                  <joint name="hip_roll_1" pos="0 0 0" axis="0 1 0"/>
                  <geom pos="0 -0.002 -0.318" quat="1 0 0 0" type="mesh" rgba="0.972549 0.529412 0.00392157 1" mesh="Hip_Roll"/>
                  <body name="thigh_1" pos="0 -0.002 -0.058">
                    <inertial pos="0.00741014 -0.00071203 -0.0734583" quat="0.999433 -0.0094094 -0.0323113 -0.00123905" mass="0.395503" diaginertia="0.0014547 0.00120217 0.000391149"/>
                    <joint name="yaw_1" pos="0 0 0" axis="0 0 1"/>
                    <geom pos="0 0 -0.26" type="mesh" rgba="0.768627 0.886275 0.952941 1" mesh="Thigh"/>
                    <body name="shin_1" pos="0.002 0 -0.16">
                      <inertial pos="-0.0164976 0 -0.12692" quat="0.99998 0 -0.00632508 0" mass="0.696938" diaginertia="0.0038417 0.00336971 0.000508003"/>
                      <joint name="knee_1" pos="0 0 0" axis="1 0 0"/>
                      <geom pos="-0.002 0 -0.1" type="mesh" rgba="0.231373 0.380392 0.705882 1" mesh="Shin"/>
                      <body name="ankle_1" pos="-0.004 0 -0.2">
                        <inertial pos="0.0130536 -0.00173308 -0.0126928" quat="0.994516 -0.098411 0.035132 -0.00437492" mass="0.328127" diaginertia="0.00054463 0.000373667 0.000212892"/>
                        <joint name="ankle_pitch_1" pos="0 0 0" axis="-1 0 0"/>
                        <geom pos="0.002 0 0.1" type="mesh" rgba="0.647059 0.647059 0.647059 1" mesh="Ankle"/>
                        <body name="foot_1" pos="0.002 0.002 -0.069" quat="0.999967 0 -0.00816426 0">
                          <inertial pos="0 -3.04468e-05 -0.0288044" quat="-0.0312858 0.706414 -0.0312858 0.706414" mass="0.38693" diaginertia="0.000471902 0.00028466 0.000284384"/>
                          <joint name="ankle_roll_1" pos="0 0 0" axis="0 1 0"/>
                          <geom pos="0 -0.002 0.169" quat="1 0 0 0" type="mesh" rgba="0.615686 0.811765 0.929412 1" mesh="Foot"/>
                        </body>
                      </body>
                    </body>
                  </body>
                </body>
              </body>
            </body>
            <body name="hip" pos="-0.03 -0.07 -0.0791376" quat="1.76038e-12 1.32679e-06 1 1.32679e-06">
              <inertial pos="0.02 0 0" mass="0.114847" diaginertia="0.000203049 0.000116837 0.000116837"/>
              <geom pos="0.098 0 -0.318" type="mesh" rgba="0.980392 0.713726 0.00392157 1" mesh="Hip"/>
              <body name="hip_pitch" pos="0.04 0 0" quat="1.32679e-06 1 0 0">
                <inertial pos="0.044959 0.0174626 -3.01048e-12" quat="0.399887 0.399887 0.583173 0.583173" mass="0.205193" diaginertia="0.000419309 0.000297906 0.000280298"/>
                <joint name="hip_pitch" pos="0 0 0" axis="-1 0 0"/>
                <geom pos="0.058 0 -0.318" quat="1 0 0 0" type="mesh" rgba="0.498039 0.498039 0.498039 1" mesh="Hip_Pitch"/>
                <body name="hip_roll" pos="0.058 0.002 0">
                  <inertial pos="4.91788e-12 -0.0124546 -0.0250019" quat="0.68358 0.180882 -0.180882 0.68358" mass="0.342742" diaginertia="0.000622632 0.000452239 0.000414222"/>
                  <joint name="hip_roll" pos="0 0 0" axis="0 -1 0"/>
                  <geom pos="0 -0.002 -0.318" quat="1 0 0 0" type="mesh" rgba="0.972549 0.529412 0.00392157 1" mesh="Hip_Roll"/>
                  <body name="thigh" pos="0 -0.002 -0.058" quat="0.999935 0 0 -0.0113648">
                    <inertial pos="0.00741014 -0.00071203 -0.0734583" quat="0.999433 -0.0094094 -0.0323113 -0.00123905" mass="0.395503" diaginertia="0.0014547 0.00120217 0.000391149"/>
                    <joint name="yaw" pos="0 0 0" axis="0 0 -1"/>
                    <geom pos="0 0 -0.26" type="mesh" rgba="0.768627 0.886275 0.952941 1" mesh="Thigh"/>
                    <body name="shin" pos="0.002 0 -0.16">
                      <inertial pos="-0.0164976 0 -0.12692" quat="0.99998 0 -0.00632508 0" mass="0.696938" diaginertia="0.0038417 0.00336971 0.000508003"/>
                      <joint name="knee" pos="0 0 0" axis="-1 0 0"/>
                      <geom pos="-0.002 0 -0.1" type="mesh" rgba="0.231373 0.380392 0.705882 1" mesh="Shin"/>
                      <body name="ankle" pos="-0.004 0 -0.2" quat="1 0 0 0">
                        <inertial pos="0.0130536 -0.00173308 -0.0126928" quat="0.994516 -0.098411 0.035132 -0.00437492" mass="0.328127" diaginertia="0.00054463 0.000373667 0.000212892"/>
                        <joint name="ankle_pitch" pos="0 0 0" axis="1 0 0"/>
                        <geom pos="0.002 0 0.1" type="mesh" rgba="0.647059 0.647059 0.647059 1" mesh="Ankle"/>
                        <body name="foot" pos="0.002 0.002 -0.069" quat="0.999967 0 -0.00816426 0">
                          <inertial pos="0 -3.04468e-05 -0.0288044" quat="-0.0312858 0.706414 -0.0312858 0.706414" mass="0.38693" diaginertia="0.000471902 0.00028466 0.000284384"/>
                          <joint name="ankle_roll" pos="0 0 0" axis="0 -1 0"/>
                          <geom pos="0 -0.002 0.169" quat="1 0 0 0" type="mesh" rgba="0.615686 0.811765 0.929412 1" mesh="Foot"/>
                        </body>
                      </body>
                    </body>
                  </body>
                </body>
              </body>
            </body>
            <body name="part_2" pos="-0.0589806 -0.07 0.0538186">
              <inertial pos="0.0589806 0.0116765 0.108266" quat="0.705692 -0.0447117 0.0447117 0.705692" mass="2.996" diaginertia="0.0335624 0.0270255 0.0240902"/>
              <joint name="revolute_1" pos="0 0 0" axis="1 0 0"/>
              <geom pos="0.0589806 0 -0.0699562" quat="1 0 0 0" type="mesh" rgba="0.917647 0.917647 0.917647 1" mesh="Part_2"/>
              <body name="part_1" pos="0.163045 0.0301369 0.164551">
                <inertial pos="0.03 0 0" mass="0.17227" diaginertia="0.000304573 0.000203968 0.000203968"/>
                <geom pos="0.10811 0 0" type="mesh" rgba="0.615686 0.811765 0.929412 1" mesh="Part_1"/>
                <body name="part_2_1" pos="0.06 0 0">
                  <inertial pos="0.0329553 -0.00486958 -0.0195905" quat="0.983005 -0.0982669 -0.126494 0.0896855" mass="0.179724" diaginertia="0.000409968 0.000383742 0.000188393"/>
                  <joint name="shoulder_yaw" pos="0 0 0" axis="1 0 0"/>
                  <geom pos="0.0481099 0 0" type="mesh" rgba="0.647059 0.647059 0.647059 1" mesh="Part_2_1"/>
                  <body name="part_3" pos="0.0481099 -0.002 -0.054">
                    <inertial pos="-2.07904e-11 0.00576515 -0.0427323" quat="0.701822 -0.0862896 0.0862896 0.701822" mass="0.236776" diaginertia="0.000524759 0.000429886 0.000362666"/>
                    <joint name="shoulder_roll" pos="0 0 0" axis="0 1 0"/>
                    <geom pos="0 0.002 0.054" quat="1 0 0 0" type="mesh" rgba="0.917647 0.917647 0.917647 1" mesh="Part_3"/>
                    <body name="part_4" pos="0 0.002 -0.094">
                      <inertial pos="-0.0227382 -4.06552e-12 -0.0592339" quat="0.996769 0 0.0803246 0" mass="0.763075" diaginertia="0.00123728 0.000926563 0.000663713"/>
                      <joint name="shoulder_pitch" pos="0 0 0" axis="0 0 1"/>
                      <geom pos="0 0 0.148" type="mesh" rgba="0.768627 0.886275 0.952941 1" mesh="Part_4"/>
                      <body name="part_5" pos="-0.002 0 -0.072" quat="0.999968 -0.00800536 0 0">
                        <inertial pos="0.000114307 0 -0.0911714" quat="0.998341 0 0.0575707 0" mass="2.51045" diaginertia="0.00990149 0.00900951 0.00243744"/>
                        <joint name="elbow" pos="0 0 0" axis="1 0 0"/>
                        <geom pos="0.002 0 0.22" type="mesh" rgba="0.972549 0.529412 0.00392157 1" mesh="Part_5"/>
                      </body>
                    </body>
                  </body>
                </body>
              </body>
              <body name="part_1_1" pos="-0.0450837 0.0301369 0.164551" quat="1.76038e-12 1.32679e-06 1 1.32679e-06">
                <inertial pos="0.03 0 0" mass="0.17227" diaginertia="0.000304573 0.000203968 0.000203968"/>
                <geom pos="0.10811 0 0" type="mesh" rgba="0.615686 0.811765 0.929412 1" mesh="Part_1"/>
                <body name="part_2_2" pos="0.06 0 0" quat="1.32679e-06 1 0 0">
                  <inertial pos="0.0329553 -0.00486958 -0.0195905" quat="0.983005 -0.0982669 -0.126494 0.0896855" mass="0.179724" diaginertia="0.000409968 0.000383742 0.000188393"/>
                  <joint name="shoulder_yaw_1" pos="0 0 0" axis="-1 0 0"/>
                  <geom pos="0.0481099 0 0" type="mesh" rgba="0.647059 0.647059 0.647059 1" mesh="Part_2_1"/>
                  <body name="part_3_1" pos="0.0481099 -0.002 -0.054">
                    <inertial pos="-2.07904e-11 0.00576515 -0.0427323" quat="0.701822 -0.0862896 0.0862896 0.701822" mass="0.236776" diaginertia="0.000524759 0.000429886 0.000362666"/>
                    <joint name="shoulder_roll_1" pos="0 0 0" axis="0 -1 0"/>
                    <geom pos="0 0.002 0.054" quat="1 0 0 0" type="mesh" rgba="0.917647 0.917647 0.917647 1" mesh="Part_3"/>
                    <body name="part_4_1" pos="0 0.002 -0.094" quat="0.999539 0 0 -0.0303573">
                      <inertial pos="-0.0227382 -4.06552e-12 -0.0592339" quat="0.996769 0 0.0803246 0" mass="0.763075" diaginertia="0.00123728 0.000926563 0.000663713"/>
                      <joint name="shoulder_pitch_1" pos="0 0 0" axis="0 0 -1"/>
                      <geom pos="0 0 0.148" type="mesh" rgba="0.768627 0.886275 0.952941 1" mesh="Part_4"/>
                      <body name="part_5_1" pos="-0.002 0 -0.072" quat="0.999968 -0.00800536 0 0">
                        <inertial pos="0.000114307 0 -0.0911714" quat="0.998341 0 0.0575707 0" mass="2.51045" diaginertia="0.00990149 0.00900951 0.00243744"/>
                        <joint name="elbow_1" pos="0 0 0" axis="-1 0 0"/>
                        <geom pos="0.002 0 0.22" type="mesh" rgba="0.972549 0.529412 0.00392157 1" mesh="Part_5"/>
                      </body>
                    </body>
                  </body>
                </body>
              </body>
            </body>
          </body>
        </body>
      </frame>
    </body>
  </worldbody>

  <contact>
    <exclude body1="pelvis" body2="hip_1"/>
    <exclude body1="pelvis" body2="hip"/>
    <exclude body1="pelvis" body2="part_2"/>
    <exclude body1="hip_1" body2="hip_pitch_1"/>
    <exclude body1="hip_pitch_1" body2="hip_roll_1"/>
    <exclude body1="hip_roll_1" body2="thigh_1"/>
    <exclude body1="thigh_1" body2="shin_1"/>
    <exclude body1="shin_1" body2="ankle_1"/>
    <exclude body1="ankle_1" body2="foot_1"/>
    <exclude body1="hip" body2="hip_pitch"/>
    <exclude body1="hip_pitch" body2="hip_roll"/>
    <exclude body1="hip_roll" body2="thigh"/>
    <exclude body1="thigh" body2="shin"/>
    <exclude body1="shin" body2="ankle"/>
    <exclude body1="ankle" body2="foot"/>
    <exclude body1="part_2" body2="part_1"/>
    <exclude body1="part_2" body2="part_1_1"/>
    <exclude body1="part_1" body2="part_2_1"/>
    <exclude body1="part_2_1" body2="part_3"/>
    <exclude body1="part_3" body2="part_4"/>
    <exclude body1="part_4" body2="part_5"/>
    <exclude body1="part_1_1" body2="part_2_2"/>
    <exclude body1="part_2_2" body2="part_3_1"/>
    <exclude body1="part_3_1" body2="part_4_1"/>
    <exclude body1="part_4_1" body2="part_5_1"/>
  </contact>

  <actuator>
    <general name="hip_pitch_1_motor" joint="hip_pitch_1" ctrlrange="-36 36" forcelimited="true" forcerange="-36 36"/>
    <general name="hip_roll_1_motor" joint="hip_roll_1" ctrlrange="-36 36" forcelimited="true" forcerange="-36 36"/>
    <general name="yaw_1_motor" joint="yaw_1" ctrlrange="-36 36" forcelimited="true" forcerange="-36 36"/>
    <general name="knee_1_motor" joint="knee_1" ctrlrange="-36 36" forcelimited="true" forcerange="-36 36" gear="-1 0 0 0 0 0"/>
    <general name="ankle_pitch_1_motor" joint="ankle_pitch_1" ctrlrange="-12 12" forcelimited="true" forcerange="-12 12"/>
    <general name="ankle_roll_1_motor" joint="ankle_roll_1" ctrlrange="-12 12" forcelimited="true" forcerange="-12 12"/>
    <general name="hip_pitch_motor" joint="hip_pitch" ctrlrange="-36 36" forcelimited="true" forcerange="-36 36"/>
    <general name="hip_roll_motor" joint="hip_roll" ctrlrange="-36 36" forcelimited="true" forcerange="-36 36"/>
    <general name="yaw_motor" joint="yaw" ctrlrange="-36 36" forcelimited="true" forcerange="-36 36"/>
    <general name="knee_motor" joint="knee" ctrlrange="-36 36" forcelimited="true" forcerange="-36 36" gear="-1 0 0 0 0 0"/>
    <general name="ankle_pitch_motor" joint="ankle_pitch" ctrlrange="-12 12" forcelimited="true" forcerange="-12 12"/>
    <general name="ankle_roll_motor" joint="ankle_roll" ctrlrange="-12 12" forcelimited="true" forcerange="-12 12"/>
    <general name="revolute_1_motor" joint="revolute_1" ctrlrange="-36 36" forcelimited="true" forcerange="-36 36"/>
    <general name="shoulder_yaw_motor" joint="shoulder_yaw" ctrlrange="-36 36" forcelimited="true" forcerange="-36 36"/>
    <general name="shoulder_roll_motor" joint="shoulder_roll" ctrlrange="-36 36" forcelimited="true" forcerange="-36 36"/>
    <general name="shoulder_pitch_motor" joint="shoulder_pitch" ctrlrange="-36 36" forcelimited="true" forcerange="-36 36"/>
    <general name="elbow_motor" joint="elbow" ctrlrange="-36 36" forcelimited="true" forcerange="-36 36" gear="-1 0 0 0 0 0"/>
    <general name="shoulder_yaw_1_motor" joint="shoulder_yaw_1" ctrlrange="-36 36" forcelimited="true" forcerange="-36 36"/>
    <general name="shoulder_roll_1_motor" joint="shoulder_roll_1" ctrlrange="-36 36" forcelimited="true" forcerange="-36 36"/>
    <general name="shoulder_pitch_1_motor" joint="shoulder_pitch_1" ctrlrange="-36 36" forcelimited="true" forcerange="-36 36"/>
    <general name="elbow_1_motor" joint="elbow_1" ctrlrange="-36 36" forcelimited="true" forcerange="-36 36" gear="-1 0 0 0 0 0"/>
  </actuator>
</mujoco>
