<!--URDF generated by ONSHAPE BY PTC INC, 1.215-->
<robot name="full_assembly">
    <link name="ankle">
        <inertial>
            <mass value="0.328127" />
            <origin xyz="0.0130536 -0.00173308 -0.0126928" rpy="0 -0 0" />
            <inertia ixx="0.000542969" ixy="-4.88587e-06" ixz="-2.28946e-05" iyy="0.000367568" iyz="-3.05506e-05" izz="0.000220652" />
        </inertial>
        <visual>
            <origin xyz="0.002 -6.93889e-18 0.1" rpy="0 -0 0" />
            <geometry>
                <mesh filename="package://full_assembly/meshes/Ankle.obj" scale="1 1 1" />
            </geometry>
            <material name="0.647059_0.647059_0.647059_0.000000_0.000000">
                <color rgba="0.647059 0.647059 0.647059 1" />
            </material>
        </visual>
    </link>
    <link name="ankle__1_">
        <inertial>
            <mass value="1e-09" />
            <origin xyz="0 0 0" rpy="0 -0 0" />
            <inertia ixx="4e-14" ixy="0" ixz="0" iyy="4e-14" iyz="0" izz="4e-14" />
        </inertial>
    </link>
    <link name="foot">
        <inertial>
            <mass value="0.38693" />
            <origin xyz="0 -3.04468e-05 -0.0288044" rpy="0 -0 0" />
            <inertia ixx="0.000284384" ixy="0" ixz="0" iyy="0.000286123" iyz="-1.6488e-05" izz="0.000470439" />
        </inertial>
        <visual>
            <origin xyz="0 -0.002 0.169" rpy="0 -0 0" />
            <geometry>
                <mesh filename="package://full_assembly/meshes/Foot.obj" scale="1 1 1" />
            </geometry>
            <material name="0.615686_0.811765_0.929412_0.000000_0.000000">
                <color rgba="0.615686 0.811765 0.929412 1" />
            </material>
        </visual>
    </link>
    <link name="foot__1_">
        <inertial>
            <mass value="1e-09" />
            <origin xyz="0 0 0" rpy="0 -0 0" />
            <inertia ixx="4e-14" ixy="0" ixz="0" iyy="4e-14" iyz="0" izz="4e-14" />
        </inertial>
    </link>
    <link name="hip">
        <inertial>
            <mass value="0.114847" />
            <origin xyz="0.02 -1.43996e-16 0" rpy="0 -0 0" />
            <inertia ixx="0.000203049" ixy="0" ixz="0" iyy="0.000116837" iyz="0" izz="0.000116837" />
        </inertial>
        <visual>
            <origin xyz="0.098 5.52943e-17 -0.318" rpy="0 -0 0" />
            <geometry>
                <mesh filename="package://full_assembly/meshes/Hip.obj" scale="1 1 1" />
            </geometry>
            <material name="0.980392_0.713725_0.003922_0.000000_0.000000">
                <color rgba="0.980392 0.713726 0.00392157 1" />
            </material>
        </visual>
    </link>
    <link name="hip__1_">
        <inertial>
            <mass value="1e-09" />
            <origin xyz="0 0 0" rpy="0 -0 0" />
            <inertia ixx="4e-14" ixy="0" ixz="0" iyy="4e-14" iyz="0" izz="4e-14" />
        </inertial>
    </link>
    <link name="hip_pitch">
        <inertial>
            <mass value="0.205193" />
            <origin xyz="0.044959 0.0174626 -3.01048e-12" rpy="0 -0 0" />
            <inertia ixx="0.00029835" ixy="-4.67287e-05" ixz="2.93499e-13" iyy="0.000401257" iyz="8.13491e-13" izz="0.000297906" />
        </inertial>
        <visual>
            <origin xyz="0.058 2.0383e-17 -0.318" rpy="0 -0 0" />
            <geometry>
                <mesh filename="package://full_assembly/meshes/Hip_Pitch.obj" scale="1 1 1" />
            </geometry>
            <material name="0.498039_0.498039_0.498039_0.000000_0.000000">
                <color rgba="0.498039 0.498039 0.498039 1" />
            </material>
        </visual>
    </link>
    <link name="hip_pitch__1_">
        <inertial>
            <mass value="1e-09" />
            <origin xyz="0 0 0" rpy="0 -0 0" />
            <inertia ixx="4e-14" ixy="0" ixz="0" iyy="4e-14" iyz="0" izz="4e-14" />
        </inertial>
    </link>
    <link name="hip_roll">
        <inertial>
            <mass value="0.342742" />
            <origin xyz="4.91788e-12 -0.0124546 -0.0250019" rpy="0 -0 0" />
            <inertia ixx="0.000452239" ixy="-7.11353e-13" ixz="7.71738e-14" iyy="0.000571651" iyz="8.95872e-05" izz="0.000465203" />
        </inertial>
        <visual>
            <origin xyz="7.51078e-18 -0.002 -0.318" rpy="0 -0 0" />
            <geometry>
                <mesh filename="package://full_assembly/meshes/Hip_Roll.obj" scale="1 1 1" />
            </geometry>
            <material name="0.972549_0.529412_0.003922_0.000000_0.000000">
                <color rgba="0.972549 0.529412 0.00392157 1" />
            </material>
        </visual>
    </link>
    <link name="hip_roll__1_">
        <inertial>
            <mass value="1e-09" />
            <origin xyz="0 0 0" rpy="0 -0 0" />
            <inertia ixx="4e-14" ixy="0" ixz="0" iyy="4e-14" iyz="0" izz="4e-14" />
        </inertial>
    </link>
    <link name="part_1_1">
        <inertial>
            <mass value="0.17227" />
            <origin xyz="0.03 -6.501e-17 1.82677e-16" rpy="0 -0 0" />
            <inertia ixx="0.000304573" ixy="0" ixz="0" iyy="0.000203968" iyz="0" izz="0.000203968" />
        </inertial>
        <visual>
            <origin xyz="0.10811 -1.22465e-18 0" rpy="0 -0 0" />
            <geometry>
                <mesh filename="package://full_assembly/meshes/Part_1.obj" scale="1 1 1" />
            </geometry>
            <material name="0.615686_0.811765_0.929412_0.000000_0.000000">
                <color rgba="0.615686 0.811765 0.929412 1" />
            </material>
        </visual>
    </link>
    <link name="part_1__1_">
        <inertial>
            <mass value="1e-09" />
            <origin xyz="0 0 0" rpy="0 -0 0" />
            <inertia ixx="4e-14" ixy="0" ixz="0" iyy="4e-14" iyz="0" izz="4e-14" />
        </inertial>
    </link>
    <link name="part_2">
        <inertial>
            <mass value="2.996" />
            <origin xyz="0.0589806 0.0116765 0.108266" rpy="0 -0 0" />
            <inertia ixx="0.0270255" ixy="0" ixz="0" iyy="0.0334115" iyz="-0.00118593" izz="0.0242411" />
        </inertial>
        <visual>
            <origin xyz="0.0589806 1.38778e-17 -0.0699562" rpy="0 -0 0" />
            <geometry>
                <mesh filename="package://full_assembly/meshes/Part_2.obj" scale="1 1 1" />
            </geometry>
            <material name="0.917647_0.917647_0.917647_0.000000_0.000000">
                <color rgba="0.917647 0.917647 0.917647 1" />
            </material>
        </visual>
    </link>
    <link name="part_2_1">
        <inertial>
            <mass value="0.179724" />
            <origin xyz="0.0329553 -0.00486958 -0.0195905" rpy="0 -0 0" />
            <inertia ixx="0.000393652" ixy="1.3893e-05" ixz="5.51231e-05" iyy="0.000379124" iyz="-3.03795e-05" izz="0.000209327" />
        </inertial>
        <visual>
            <origin xyz="0.0481099 -1.22465e-18 0" rpy="0 -0 0" />
            <geometry>
                <mesh filename="package://full_assembly/meshes/Part_2_1.obj" scale="1 1 1" />
            </geometry>
            <material name="0.647059_0.647059_0.647059_0.000000_0.000000">
                <color rgba="0.647059 0.647059 0.647059 1" />
            </material>
        </visual>
    </link>
    <link name="part_2__1_">
        <inertial>
            <mass value="1e-09" />
            <origin xyz="0 0 0" rpy="0 -0 0" />
            <inertia ixx="4e-14" ixy="0" ixz="0" iyy="4e-14" iyz="0" izz="4e-14" />
        </inertial>
    </link>
    <link name="part_3">
        <inertial>
            <mass value="0.236776" />
            <origin xyz="-2.07904e-11 0.00576515 -0.0427323" rpy="0 -0 0" />
            <inertia ixx="0.000429886" ixy="-6.71931e-13" ixz="-8.84514e-14" iyy="0.000515247" iyz="-3.80957e-05" izz="0.000372178" />
        </inertial>
        <visual>
            <origin xyz="1.73472e-18 0.002 0.054" rpy="0 -0 0" />
            <geometry>
                <mesh filename="package://full_assembly/meshes/Part_3.obj" scale="1 1 1" />
            </geometry>
            <material name="0.917647_0.917647_0.917647_0.000000_0.000000">
                <color rgba="0.917647 0.917647 0.917647 1" />
            </material>
        </visual>
    </link>
    <link name="part_3__1_">
        <inertial>
            <mass value="1e-09" />
            <origin xyz="0 0 0" rpy="0 -0 0" />
            <inertia ixx="4e-14" ixy="0" ixz="0" iyy="4e-14" iyz="0" izz="4e-14" />
        </inertial>
    </link>
    <link name="part_4_1">
        <inertial>
            <mass value="0.763075" />
            <origin xyz="-0.0227382 -4.06552e-12 -0.0592339" rpy="0 -0 0" />
            <inertia ixx="0.00122257" ixy="-3.25123e-13" ixz="-9.06597e-05" iyy="0.000926563" iyz="-4.80575e-13" izz="0.00067842" />
        </inertial>
        <visual>
            <origin xyz="0 -2.44929e-18 0.148" rpy="0 -0 0" />
            <geometry>
                <mesh filename="package://full_assembly/meshes/Part_4.obj" scale="1 1 1" />
            </geometry>
            <material name="0.768627_0.886275_0.952941_0.000000_0.000000">
                <color rgba="0.768627 0.886275 0.952941 1" />
            </material>
        </visual>
    </link>
    <link name="part_4__1_">
        <inertial>
            <mass value="1e-09" />
            <origin xyz="0 0 0" rpy="0 -0 0" />
            <inertia ixx="4e-14" ixy="0" ixz="0" iyy="4e-14" iyz="0" izz="4e-14" />
        </inertial>
    </link>
    <link name="part_5_1">
        <inertial>
            <mass value="2.51045" />
            <origin xyz="0.000114307 1.48718e-18 -0.0911714" rpy="0 -0 0" />
            <inertia ixx="0.00980286" ixy="0" ixz="-0.000852308" iyy="0.00900951" iyz="0" izz="0.00253607" />
        </inertial>
        <visual>
            <origin xyz="0.002 0 0.22" rpy="0 -0 0" />
            <geometry>
                <mesh filename="package://full_assembly/meshes/Part_5.obj" scale="1 1 1" />
            </geometry>
            <material name="0.972549_0.529412_0.003922_0.000000_0.000000">
                <color rgba="0.972549 0.529412 0.00392157 1" />
            </material>
        </visual>
    </link>
    <link name="part_5__1_">
        <inertial>
            <mass value="1e-09" />
            <origin xyz="0 0 0" rpy="0 -0 0" />
            <inertia ixx="4e-14" ixy="0" ixz="0" iyy="4e-14" iyz="0" izz="4e-14" />
        </inertial>
    </link>
    <link name="pelvis">
        <inertial>
            <mass value="4.24496" />
            <origin xyz="6.7273e-18 -0.0675224 -0.0165033" rpy="0 -0 0" />
            <inertia ixx="0.0142013" ixy="0" ixz="0" iyy="0.0134283" iyz="-0.000383277" izz="0.0100864" />
        </inertial>
        <visual>
            <origin xyz="3.47083e-18 -0.07 -0.0161376" rpy="0 -0 0" />
            <geometry>
                <mesh filename="package://full_assembly/meshes/Pelvis.obj" scale="1 1 1" />
            </geometry>
            <material name="0.647059_0.647059_0.647059_0.000000_0.000000">
                <color rgba="0.647059 0.647059 0.647059 1" />
            </material>
        </visual>
    </link>
    <link name="root">
        <visual>
            <origin xyz="-0.212174 -0.0363409 0.218342" rpy="0.0160109 2.68633e-17 -3.14159" />
            <geometry>
                <mesh filename="package://full_assembly/meshes/Part_5.obj" scale="1 1 1" />
            </geometry>
            <material name="0.972549_0.529412_0.003922_0.000000_0.000000">
                <color rgba="0.972549 0.529412 0.00392157 1" />
            </material>
        </visual>
        <visual>
            <origin xyz="-0.212174 -0.0398631 0.21837" rpy="3.14159 -0 3.14159" />
            <geometry>
                <mesh filename="package://full_assembly/meshes/Part_2_Mirrored.obj" scale="1 1 1" />
            </geometry>
            <material name="0.972549_0.529412_0.003922_0.000000_0.000000">
                <texture />
                <color rgba="0.972549 0.529412 0.00392157 1" />
            </material>
        </visual>
        <visual>
            <origin xyz="-0.212174 -0.0398631 0.21837" rpy="3.14159 -0 3.14159" />
            <geometry>
                <mesh filename="package://full_assembly/meshes/Part_1.obj" scale="1 1 1" />
            </geometry>
            <material name="0.615686_0.811765_0.929412_0.000000_0.000000">
                <texture />
                <color rgba="0.615686 0.811765 0.929412 1" />
            </material>
        </visual>
        <visual>
            <origin xyz="-0.212174 -0.0398631 0.21837" rpy="5.55112e-17 3.07902e-48 -3.14159" />
            <geometry>
                <mesh filename="package://full_assembly/meshes/Part_4.obj" scale="1 1 1" />
            </geometry>
            <material name="0.768627_0.886275_0.952941_0.000000_0.000000">
                <texture />
                <color rgba="0.768627 0.886275 0.952941 1" />
            </material>
        </visual>
        <visual>
            <origin xyz="-0.212174 -0.0398631 0.21837" rpy="3.14159 -0 3.14159" />
            <geometry>
                <mesh filename="package://full_assembly/meshes/Part_3_Mirrored.obj" scale="1 1 1" />
            </geometry>
            <material name="0.972549_0.529412_0.003922_0.000000_0.000000">
                <texture />
                <color rgba="0.972549 0.529412 0.00392157 1" />
            </material>
        </visual>
        <visual>
            <origin xyz="-0.125241 -0.07 -0.39716" rpy="3.73629e-16 0.0163287 -9.47479e-15" />
            <geometry>
                <mesh filename="package://full_assembly/meshes/Foot.obj" scale="1 1 1" />
            </geometry>
            <material name="0.615686_0.811765_0.929412_0.000000_0.000000">
                <texture />
                <color rgba="0.615686 0.811765 0.929412 1" />
            </material>
        </visual>
        <visual>
            <origin xyz="-0.128 -0.0699997 0.238862" rpy="-3.14159 -8.08668e-07 -3.14159" />
            <geometry>
                <mesh filename="package://full_assembly/meshes/Hip_Pitch.obj" scale="1 1 1" />
            </geometry>
            <material name="0.498039_0.498039_0.498039_0.000000_0.000000">
                <texture />
                <color rgba="0.498039 0.498039 0.498039 1" />
            </material>
        </visual>
        <visual>
            <origin xyz="-0.128 -0.07 -0.397138" rpy="2.8519e-14 -2.51188e-15 -3.14159" />
            <geometry>
                <mesh filename="package://full_assembly/meshes/Shin.obj" scale="1 1 1" />
            </geometry>
            <material name="0.231373_0.380392_0.705882_0.000000_0.000000">
                <texture />
                <color rgba="0.231373 0.380392 0.705882 1" />
            </material>
        </visual>
        <visual>
            <origin xyz="-0.128 -0.07 -0.397138" rpy="-1.25631e-15 -1.87541e-16 3.14159" />
            <geometry>
                <mesh filename="package://full_assembly/meshes/Thigh.obj" scale="1 1 1" />
            </geometry>
            <material name="0.768627_0.886275_0.952941_0.000000_0.000000">
                <texture />
                <color rgba="0.768627 0.886275 0.952941 1" />
            </material>
        </visual>
        <visual>
            <origin xyz="-0.128 -0.07 -0.397138" rpy="3.14159 -1.64452e-15 -3.14159" />
            <geometry>
                <mesh filename="package://full_assembly/meshes/Ankle_Mirrored.obj" scale="1 1 1" />
            </geometry>
            <material name="0.972549_0.529412_0.003922_0.000000_0.000000">
                <texture />
                <color rgba="0.972549 0.529412 0.00392157 1" />
            </material>
        </visual>
        <visual>
            <origin xyz="-0.128 -0.07 -0.397138" rpy="0 -0 0" />
            <geometry>
                <mesh filename="package://full_assembly/meshes/Hip_Roll.obj" scale="1 1 1" />
            </geometry>
            <material name="0.972549_0.529412_0.003922_0.000000_0.000000">
                <texture />
                <color rgba="0.972549 0.529412 0.00392157 1" />
            </material>
        </visual>
        <visual>
            <origin xyz="-0.128 -0.07 0.238862" rpy="3.14159 -0 3.14159" />
            <geometry>
                <mesh filename="package://full_assembly/meshes/Hip.obj" scale="1 1 1" />
            </geometry>
            <material name="0.980392_0.713725_0.003922_0.000000_0.000000">
                <texture />
                <color rgba="0.980392 0.713726 0.00392157 1" />
            </material>
        </visual>
    </link>
    <link name="shin">
        <inertial>
            <mass value="0.696938" />
            <origin xyz="-0.0164976 -3.14274e-17 -0.12692" rpy="0 -0 0" />
            <inertia ixx="0.00384117" ixy="0" ixz="4.21676e-05" iyy="0.00336971" iyz="0" izz="0.000508536" />
        </inertial>
        <visual>
            <origin xyz="-0.002 -1.38778e-17 -0.1" rpy="0 -0 0" />
            <geometry>
                <mesh filename="package://full_assembly/meshes/Shin.obj" scale="1 1 1" />
            </geometry>
            <material name="0.231373_0.380392_0.705882_0.000000_0.000000">
                <color rgba="0.231373 0.380392 0.705882 1" />
            </material>
        </visual>
    </link>
    <link name="shin__1_">
        <inertial>
            <mass value="1e-09" />
            <origin xyz="0 0 0" rpy="0 -0 0" />
            <inertia ixx="4e-14" ixy="0" ixz="0" iyy="4e-14" iyz="0" izz="4e-14" />
        </inertial>
    </link>
    <link name="thigh">
        <inertial>
            <mass value="0.526047" />
            <origin xyz="0.00786672 1.06677e-16 -0.0716487" rpy="0 -0 0" />
            <inertia ixx="0.00156943" ixy="0" ixz="6.72077e-05" iyy="0.00127606" iyz="0" izz="0.000446104" />
        </inertial>
        <visual>
            <origin xyz="0 1.66956e-17 -0.26" rpy="0 -0 0" />
            <geometry>
                <mesh filename="package://full_assembly/meshes/Thigh.obj" scale="1 1 1" />
            </geometry>
            <material name="0.768627_0.886275_0.952941_0.000000_0.000000">
                <color rgba="0.768627 0.886275 0.952941 1" />
            </material>
        </visual>
    </link>
    <link name="thigh__1_">
        <inertial>
            <mass value="1e-09" />
            <origin xyz="0 0 0" rpy="0 -0 0" />
            <inertia ixx="4e-14" ixy="0" ixz="0" iyy="4e-14" iyz="0" izz="4e-14" />
        </inertial>
    </link>
    <joint name="ankle_pitch" type="continuous">
        <origin xyz="-0.004 -6.93889e-18 -0.2" rpy="0 -0 0" />
        <axis xyz="1 0 0" />
        <parent link="shin__1_" />
        <child link="ankle__1_" />
        <mimic offset="0" multiplier="-1" joint="ankle_pitch_1" />
    </joint>
    <joint name="ankle_pitch_1" type="continuous">
        <origin xyz="-0.004 0 -0.2" rpy="2.81893e-17 1.43967e-29 3.46945e-18" />
        <axis xyz="1 0 0" />
        <parent link="shin" />
        <child link="ankle" />
    </joint>
    <joint name="ankle_roll" type="continuous">
        <origin xyz="0.002 0.002 -0.069" rpy="0 -0 0" />
        <axis xyz="0 -1 0" />
        <parent link="ankle__1_" />
        <child link="foot__1_" />
        <mimic offset="0" multiplier="-1" joint="ankle_roll_1" />
    </joint>
    <joint name="ankle_roll_1" type="continuous">
        <origin xyz="0.002 0.002 -0.069" rpy="1.31993e-15 -0.0163287 5.43677e-15" />
        <axis xyz="0 -1 0" />
        <parent link="ankle" />
        <child link="foot" />
    </joint>
    <joint name="fastened_1" type="fixed">
        <origin xyz="0 0 0" rpy="0 -0 0" />
        <axis xyz="0 1 0" />
        <parent link="root" />
        <child link="pelvis" />
    </joint>
    <joint name="fastened_2" type="fixed">
        <origin xyz="-0.0491293 0.07 -0.0538186" rpy="0 -0 0" />
        <axis xyz="-1 0 0" />
        <parent link="part_2" />
        <child link="part_1__1_" />
    </joint>
    <joint name="fastened_2_1" type="fixed">
        <origin xyz="0.163045 0.0301369 0.164551" rpy="0 -0 0" />
        <axis xyz="-1 0 0" />
        <parent link="part_2" />
        <child link="part_1_1" />
    </joint>
    <joint name="fastened_3" type="fixed">
        <origin xyz="-0.098 -5.52943e-17 0.318" rpy="0 -0 0" />
        <axis xyz="-1 0 0" />
        <parent link="pelvis" />
        <child link="hip__1_" />
    </joint>
    <joint name="fastened_3_1" type="fixed">
        <origin xyz="0.03 -0.07 -0.0791376" rpy="0 -0 0" />
        <axis xyz="-1 0 0" />
        <parent link="pelvis" />
        <child link="hip" />
    </joint>
    <joint name="hip_pitch" type="continuous">
        <origin xyz="0.04 3.49113e-17 1.66533e-16" rpy="0 -0 0" />
        <axis xyz="-1 0 0" />
        <parent link="hip__1_" />
        <child link="hip_pitch__1_" />
        <mimic offset="0" multiplier="-1" joint="hip_pitch_1" />
    </joint>
    <joint name="hip_pitch_1" type="continuous">
        <origin xyz="0.04 4.16334e-17 1.66533e-16" rpy="0 -0 0" />
        <axis xyz="-1 0 0" />
        <parent link="hip" />
        <child link="hip_pitch" />
    </joint>
    <joint name="hip_roll" type="continuous">
        <origin xyz="0.058 0.002 -1.66533e-16" rpy="0 -0 0" />
        <axis xyz="0 -1 0" />
        <parent link="hip_pitch__1_" />
        <child link="hip_roll__1_" />
        <mimic offset="0" multiplier="-1" joint="hip_roll_1" />
    </joint>
    <joint name="hip_roll_1" type="continuous">
        <origin xyz="0.058 0.002 -1.66533e-16" rpy="1.01424e-69 4.21297e-35 4.81482e-35" />
        <axis xyz="0 -1 0" />
        <parent link="hip_pitch" />
        <child link="hip_roll" />
    </joint>
    <joint name="knee" type="continuous">
        <origin xyz="0.002 3.05734e-17 -0.16" rpy="0 -0 0" />
        <axis xyz="-1 0 0" />
        <parent link="thigh__1_" />
        <child link="shin__1_" />
        <mimic offset="0" multiplier="-1" joint="knee_1" />
    </joint>
    <joint name="knee_1" type="continuous">
        <origin xyz="0.002 1.38778e-17 -0.16" rpy="-4.20871e-17 -1.63934e-18 -6.93889e-18" />
        <axis xyz="-1 0 0" />
        <parent link="thigh" />
        <child link="shin" />
    </joint>
    <joint name="revolute_1" type="continuous">
        <origin xyz="0.06 0 0" rpy="0 -0 0" />
        <axis xyz="1 0 0" />
        <parent link="part_1__1_" />
        <child link="part_2__1_" />
        <mimic offset="0" multiplier="-1" joint="revolute_1_1" />
    </joint>
    <joint name="revolute_1_1" type="continuous">
        <origin xyz="0.06 0 0" rpy="0 -0 0" />
        <axis xyz="1 0 0" />
        <parent link="part_1_1" />
        <child link="part_2_1" />
    </joint>
    <joint name="revolute_1_2" type="continuous">
        <origin xyz="-0.0589806 -0.07 0.0538186" rpy="0 -0 0" />
        <axis xyz="1 0 0" />
        <parent link="pelvis" />
        <child link="part_2" />
    </joint>
    <joint name="revolute_2" type="continuous">
        <origin xyz="0.0481099 -0.002 -0.054" rpy="0 -0 0" />
        <axis xyz="0 1 0" />
        <parent link="part_2__1_" />
        <child link="part_3__1_" />
        <mimic offset="0" multiplier="-1" joint="revolute_2_1" />
    </joint>
    <joint name="revolute_2_1" type="continuous">
        <origin xyz="0.0481099 -0.002 -0.054" rpy="0 -0 0" />
        <axis xyz="0 1 0" />
        <parent link="part_2_1" />
        <child link="part_3" />
    </joint>
    <joint name="revolute_3" type="continuous">
        <origin xyz="1.73472e-18 0.002 -0.094" rpy="0 -0 0" />
        <axis xyz="0 0 1" />
        <parent link="part_3__1_" />
        <child link="part_4__1_" />
        <mimic offset="0" multiplier="-1" joint="revolute_3_1" />
    </joint>
    <joint name="revolute_3_1" type="continuous">
        <origin xyz="0 0.002 -0.094" rpy="0 -0 0" />
        <axis xyz="0 0 1" />
        <parent link="part_3" />
        <child link="part_4_1" />
    </joint>
    <joint name="revolute_4" type="continuous">
        <origin xyz="-0.002 -2.44929e-18 -0.072" rpy="0 -0 0" />
        <axis xyz="1 0 0" />
        <parent link="part_4__1_" />
        <child link="part_5__1_" />
        <mimic offset="0" multiplier="-1" joint="revolute_4_1" />
    </joint>
    <joint name="revolute_4_1" type="continuous">
        <origin xyz="-0.002 0 -0.072" rpy="-0.0160109 0 0" />
        <axis xyz="1 0 0" />
        <parent link="part_4_1" />
        <child link="part_5_1" />
    </joint>
    <joint name="yaw" type="continuous">
        <origin xyz="7.51078e-18 -0.002 -0.058" rpy="0 -0 0" />
        <axis xyz="0 6.12323e-17 -1" />
        <parent link="hip_roll__1_" />
        <child link="thigh__1_" />
        <mimic offset="0" multiplier="-1" joint="yaw_1" />
    </joint>
    <joint name="yaw_1" type="continuous">
        <origin xyz="0 -0.002 -0.058" rpy="3.65211e-18 -1.83011e-18 3.46945e-18" />
        <axis xyz="0 6.12323e-17 -1" />
        <parent link="hip_roll" />
        <child link="thigh" />
    </joint>
</robot>
