<!--URDF generated by ONSHAPE BY PTC INC, 1.215-->
<robot name="leg_assembly">
    <link name="ankle">
        <inertial>
            <mass value="0.328127" />
            <origin xyz="0.0130536 -0.00173308 -0.0126928" rpy="0 -0 0" />
            <inertia ixx="0.000542969" ixy="-4.88587e-06" ixz="-2.28946e-05" iyy="0.000367568" iyz="-3.05506e-05" izz="0.000220652" />
        </inertial>
        <visual>
            <origin xyz="0.002 -6.93889e-18 0.1" rpy="0 -0 0" />
            <geometry>
                <mesh filename="package://leg_assembly/meshes/Ankle.stl" scale="1 1 1" />
            </geometry>
            <material name="0.647059_0.647059_0.647059_0.000000_0.000000">
                <color rgba="0.647059 0.647059 0.647059 1" />
            </material>
        </visual>
    </link>
    <link name="foot">
        <inertial>
            <mass value="0.38693" />
            <origin xyz="0 -3.04468e-05 -0.0288044" rpy="0 -0 0" />
            <inertia ixx="0.000284384" ixy="0" ixz="0" iyy="0.000286123" iyz="-1.6488e-05" izz="0.000470439" />
        </inertial>
        <visual>
            <origin xyz="0 -0.002 0.169" rpy="0 -0 0" />
            <geometry>
                <mesh filename="package://leg_assembly/meshes/Foot.stl" scale="1 1 1" />
            </geometry>
            <material name="0.615686_0.811765_0.929412_0.000000_0.000000">
                <color rgba="0.615686 0.811765 0.929412 1" />
            </material>
        </visual>
    </link>
    <link name="hip">
        <inertial>
            <mass value="0.114847" />
            <origin xyz="-0.078 -1.9929e-16 0.318" rpy="0 -0 0" />
            <inertia ixx="0.000203049" ixy="0" ixz="0" iyy="0.000116837" iyz="0" izz="0.000116837" />
        </inertial>
        <visual>
            <origin xyz="0 0 0" rpy="0 -0 0" />
            <geometry>
                <mesh filename="package://leg_assembly/meshes/Hip.stl" scale="1 1 1" />
            </geometry>
            <material name="0.980392_0.713725_0.003922_0.000000_0.000000">
                <color rgba="0.980392 0.713726 0.00392157 1" />
            </material>
        </visual>
    </link>
    <link name="hip_pitch">
        <inertial>
            <mass value="0.205193" />
            <origin xyz="0.044959 0.0174626 -3.01048e-12" rpy="0 -0 0" />
            <inertia ixx="0.00029835" ixy="-4.67287e-05" ixz="2.93499e-13" iyy="0.000401257" iyz="8.13491e-13" izz="0.000297906" />
        </inertial>
        <visual>
            <origin xyz="0.058 2.0383e-17 -0.318" rpy="0 -0 0" />
            <geometry>
                <mesh filename="package://leg_assembly/meshes/Hip_Pitch.stl" scale="1 1 1" />
            </geometry>
            <material name="0.498039_0.498039_0.498039_0.000000_0.000000">
                <color rgba="0.498039 0.498039 0.498039 1" />
            </material>
        </visual>
    </link>
    <link name="hip_roll">
        <inertial>
            <mass value="0.342742" />
            <origin xyz="4.91788e-12 -0.0124546 -0.0250019" rpy="0 -0 0" />
            <inertia ixx="0.000452239" ixy="-7.11353e-13" ixz="7.71738e-14" iyy="0.000571651" iyz="8.95872e-05" izz="0.000465203" />
        </inertial>
        <visual>
            <origin xyz="7.51078e-18 -0.002 -0.318" rpy="0 -0 0" />
            <geometry>
                <mesh filename="package://leg_assembly/meshes/Hip_Roll.stl" scale="1 1 1" />
            </geometry>
            <material name="0.972549_0.529412_0.003922_0.000000_0.000000">
                <color rgba="0.972549 0.529412 0.00392157 1" />
            </material>
        </visual>
    </link>
    <link name="root" />
    <link name="shin">
        <inertial>
            <mass value="0.696938" />
            <origin xyz="-0.0164976 -3.14274e-17 -0.12692" rpy="0 -0 0" />
            <inertia ixx="0.00384117" ixy="0" ixz="4.21676e-05" iyy="0.00336971" iyz="0" izz="0.000508536" />
        </inertial>
        <visual>
            <origin xyz="-0.002 -1.38778e-17 -0.1" rpy="0 -0 0" />
            <geometry>
                <mesh filename="package://leg_assembly/meshes/Shin.stl" scale="1 1 1" />
            </geometry>
            <material name="0.231373_0.380392_0.705882_0.000000_0.000000">
                <color rgba="0.231373 0.380392 0.705882 1" />
            </material>
        </visual>
    </link>
    <link name="thigh">
        <inertial>
            <mass value="0.526047" />
            <origin xyz="0.00786672 1.06677e-16 -0.0716487" rpy="0 -0 0" />
            <inertia ixx="0.00156943" ixy="0" ixz="6.72077e-05" iyy="0.00127606" iyz="0" izz="0.000446104" />
        </inertial>
        <visual>
            <origin xyz="0 1.66956e-17 -0.26" rpy="0 -0 0" />
            <geometry>
                <mesh filename="package://leg_assembly/meshes/Thigh.stl" scale="1 1 1" />
            </geometry>
            <material name="0.768627_0.886275_0.952941_0.000000_0.000000">
                <color rgba="0.768627 0.886275 0.952941 1" />
            </material>
        </visual>
    </link>
    <joint name="ankle_pitch" type="continuous">
        <origin xyz="-0.004 -1.07553e-16 -0.2" rpy="2.81893e-17 1.43967e-29 3.46945e-18" />
        <axis xyz="1 0 0" />
        <parent link="shin" />
        <child link="ankle" />
    </joint>
    <joint name="ankle_roll" type="continuous">
        <origin xyz="0.002 0.002 -0.069" rpy="1.31993e-15 -0.0163287 5.43677e-15" />
        <axis xyz="0 -1 0" />
        <parent link="ankle" />
        <child link="foot" />
    </joint>
    <joint name="fixed_node_to_root_joint" type="fixed">
        <origin xyz="-0.076637 -0.0162221 -0.0319212" rpy="0 -0 0" />
        <axis xyz="0 0 1" />
        <parent link="root" />
        <child link="hip" />
    </joint>
    <joint name="hip_pitch" type="continuous">
        <origin xyz="-0.058 -6.93889e-18 0.318" rpy="0 -0 0" />
        <axis xyz="-1 0 0" />
        <parent link="hip" />
        <child link="hip_pitch" />
    </joint>
    <joint name="hip_roll" type="continuous">
        <origin xyz="0.058 0.002 2.22045e-16" rpy="1.01424e-69 4.21297e-35 4.81482e-35" />
        <axis xyz="0 -1 0" />
        <parent link="hip_pitch" />
        <child link="hip_roll" />
    </joint>
    <joint name="knee" type="continuous">
        <origin xyz="0.002 4.51028e-17 -0.16" rpy="-4.20871e-17 -1.63934e-18 -6.93889e-18" />
        <axis xyz="-1 0 0" />
        <parent link="thigh" />
        <child link="shin" />
    </joint>
    <joint name="yaw" type="continuous">
        <origin xyz="6.93889e-17 -0.002 -0.058" rpy="3.65211e-18 -1.83011e-18 3.46945e-18" />
        <axis xyz="0 6.12323e-17 -1" />
        <parent link="hip_roll" />
        <child link="thigh" />
    </joint>
</robot>
